Workbook

Sheet redflag_questions
A1: Questions | B1: Weights | C1: Lucas | D1: Nicolaus | E1: Alex | F1: Alex | G1: Stefan | H1: Daniel | I1: Johannes | J1: Mathias | K1: Roman | L1: Ringo | M1: Mathias | N1: Rick | O1: Benny | P1: Flavio | Q1: Andreas | R1: Markus | S1: Stefan | T1: Tobias | U1: Tilo | V1: Chris | W1: Robin | X1: Chris | Y1: Basti | Z1: Maik
A2: Sie ist zum größten Teil in ihrem Leben ohne biologischen Vater aufgewachsen. | B2: =ROUND(redflag_questions_scores!B107,2) -> 5.11 | C2: 7 | D2: 3 | E2: 5 | F2: 3 | G2: 6 | H2: 5 | I2: 7 | J2: 8 | K2: 7 | L2: 3 | M2: 4 | N2: 5 | O2: 4 | P2: 5 | Q2: 3 | R2: 7 | S2: 3 | T2: 5 | U2: 3 | V2: 1 | W2: 2 | X2: 3 | Y2: 7 | Z2: 7
A3: Sie hat eine schlechte Beziehung zu ihrem Vater. | B3: =ROUND(redflag_questions_scores!B108,2) -> 4.26 | C3: 6 | D3: 7 | E3: 7 | F3: 3 | G3: 7 | H3: 7 | I3: 6 | J3: 5 | K3: 5 | L3: 3 | M3: 3 | N3: 3 | O3: 3 | P3: 2 | Q3: 3 | R3: 5 | S3: 3 | T3: 5 | U3: 4 | V3: 1 | W3: 3 | X3: 6 | Y3: 7 | Z3: 5
A4: Ihre Mutter hatte in der Eltern Beziehung das Sagen und war eher dominant. | B4: =ROUND(redflag_questions_scores!B109,2) -> 4.06 | C4: 5 | D4: 6 | E4: 6 | F4: 3 | G4: 8 | H4: 7 | I4: 4 | J4: 5 | K4: 3 | L4: 6 | M4: 1 | N4: 7 | O4: 7 | P4: 5 | Q4: 3 | R4: 4 | S4: 4 | T4: 5 | U4: 2 | V4: 1 | W4: 3 | X4: 2 | Y4: 3 | Z4: 3
A5: Sie ist eine Feministin und gibt Männer die Schuld an der Unterdrückung der Frauen. | B5: =ROUND(redflag_questions_scores!B110,2) -> 6.13 | C5: 8 | D5: 10 | E5: 10 | F5: 5 | G5: 10 | H5: 9 | I5: 10 | J5: 10 | K5: 5 | L5: 10 | M5: 7 | N5: 9 | O5: 10 | P5: 4 | Q5: 9 | R5: 5 | S5: 7 | T5: 7 | U5: 7 | V5: 4 | W5: 9 | X5: 1 | Y5: 1 | Z5: 8
A6: Sie ist eine Single Mutter die sich freiwillig von ihrem Mann getrennt hat. | B6: =ROUND(redflag_questions_scores!B111,2) -> 4.5 | C6: 5 | D6: 10 | E6: 6 | F6: 2 | G6: 7 | H6: 2 | I6: 2 | J6: 10 | K6: 3 | L6: 4 | M6: 4 | N6: 6 | O6: 2 | P6: 2 | Q6: 5 | R6: 4 | S6: 9 | T6: 6 | U6: 3 | V6: 7 | W6: 6 | X6: 3 | Y6: 5 | Z6: 4
A7: Sie ist deutlich älter als du mindestens.5 Jahre oder mehr. | B7: =ROUND(redflag_questions_scores!B112,2) -> 4.78 | C7: 8 | D7: 8 | E7: 1 | F7: 3 | G7: 6 | H7: 5 | I7: 8 | J7: 3 | K7: 9 | L7: 5 | M7: 5 | N7: 2 | O7: 3 | P7: 2 | Q7: 4 | R7: 4 | S7: 9 | T7: 7 | U7: 8 | V7: 7 | W7: 6 | X7: 1 | Y7: 4 | Z7: 2
A8: Sie ist eine einfach oder mehrfach geschiedene Frau. | B8: =ROUND(redflag_questions_scores!B113,2) -> 6.43 | C8: 9 | D8: 10 | E8: 8 | F8: 5 | G8: 6 | H8: 3 | I8: 7 | J8: 5 | K8: 8 | L8: 5 | M8: 7 | N8: 8 | O8: 4 | P8: 8 | Q8: 6 | R8: 7 | S8: 5 | T8: 7 | U8: 6 | V8: 8 | W8: 5 | X8: 8 | Y8: 4 | Z8: 7
A9: Sie hat einen hohen Bodycount (Anzahl der Personen mit denen Sie Sex hatte). So kannst du einen normalen BodyCount berechnen: (Alter - 18) x 1.3 = BodyCount | B9: =ROUND(redflag_questions_scores!B114,2) -> 5.78 | C9: 9 | D9: 10 | E9: 8 | F9: 5 | G9: 4 | H9: 9 | I9: 8 | J9: 7 | K9: 3 | L9: 7 | M9: 5 | N9: 8 | O9: 6 | P9: 8 | Q9: 4 | R9: 8 | S9: 4 | T9: 7 | U9: 5 | V9: 1 | W9: 8 | X9: 7 | Y9: 3 | Z9: 7
A10: Sie war sehr jung (zwischen 12-16 Jahre) als Sie ihr erstes mal Sex hatte. | B10: =ROUND(redflag_questions_scores!B115,2) -> 4.35 | C10: 10 | D10: 10 | E10: 9 | F10: 2 | G10: 4 | H10: 10 | I10: 5 | J10: 6 | K10: 2 | L10: 4 | M10: 3 | N10: 6 | O10: 3 | P10: 2 | Q10: 1 | R10: 5 | S10: 1 | T10: 4 | U10: 4 | V10: 1 | W10: 2 | X10: 3 | Y10: 6 | Z10: 5
A11: Die meisten und besten Ihrer Freundinnen sind Party Girls. | B11: =ROUND(redflag_questions_scores!B116,2) -> 4.8 | C11: 9 | D11: 8 | E11: 6 | F11: 3 | G11: 4 | H11: 5 | I11: 3 | J11: 5 | K11: 2 | L11: 8 | M11: 4 | N11: 8 | O11: 6 | P11: 1 | Q11: 5 | R11: 7 | S11: 6 | T11: 4 | U11: 7 | V11: 2 | W11: 9 | X11: 8 | Y11: 3 | Z11: 9
A12: Sie ist auf Social Media sehr aktiv und sucht dort Bestätigung. Sie hat auf einer Plattform über 800 Follower. | B12: =ROUND(redflag_questions_scores!B117,2) -> 5.12 | C12: 6 | D12: 7 | E12: 8 | F12: 5 | G12: 5 | H12: 7 | I12: 8 | J12: 4 | K12: 2 | L12: 10 | M12: 7 | N12: 10 | O12: 8 | P12: 9 | Q12: 8 | R12: 6 | S12: 6 | T12: 7 | U12: 5 | V12: 8 | W12: 5 | X12: 10 | Y12: 7 | Z12: 5
A13: Sie hat sehr häufig ihr Smartphone bei euren Treffen in der Hand beziehungsweise legt das Handy direkt vor sich auf den Tisch. | B13: =ROUND(redflag_questions_scores!B118,2) -> 4.05 | C13: 5 | D13: 4 | E13: 7 | F13: 4 | G13: 8 | H13: 8 | I13: 6 | J13: 4 | K13: 5 | L13: 6 | M13: 6 | N13: 5 | O13: 8 | P13: 7 | Q13: 7 | R13: 7 | S13: 3 | T13: 7 | U13: 6 | V13: 5 | W13: 8 | X13: 3 | Y13: 8 | Z13: 8
... A66: Sie kann nicht klar kommunizieren. | B66: =ROUND(redflag_questions_scores!B171,2) -> 4.79 | C66: 10 | D66: 8 | E66: 5 | F66: 4 | G66: 5 | H66: 9 | I66: 5 | J66: 4 | K66: 10 | L66: 7 | M66: 10 | N66: 7 | O66: 9 | P66: 3 | Q66: 8 | R66: 10 | S66: 6 | T66: 6 | U66: 8 | V66: 7 | W66: 6 | X66: 4 | Y66: 7 | Z66: 5

Sheet printable
A1: Questions | B1: Weights
A2: Sie ist Trans oder Gender Fluid und kennt Ihre Identität nicht. | B2: =ROUND(redflag_questions_scores!B147,2) -> 7.25
A3: Sie hat einen moralisch gesehen einen schlechten Freundeskreis. | B3: =ROUND(redflag_questions_scores!B120,2) -> 7.17
A4: Sie verletzt sich körperlich selbst. | B4: =ROUND(redflag_questions_scores!B134,2) -> 7.16
A5: Sie benutzt dich als Vertrauter ist aber kein Vertrauter für dich. | B5: =ROUND(redflag_questions_scores!B161,2) -> 7.01
A6: Sie stellt dich vor anderen Bloß wenn sie nicht in deinem Team mitspielt. Sie hält nicht zu dir in sozialen Situationen. | B6: =ROUND(redflag_questions_scores!B144,2) -> 6.45
A7: Sie ist eine einfach oder mehrfach geschiedene Frau. | B7: =ROUND(redflag_questions_scores!B113,2) -> 6.43
A8: Sie ist häufig unzuverlässig. | B8: =ROUND(redflag_questions_scores!B168,2) -> 6.42
A9: Sie nörgelt häufig rum und gibt sich mit nichts zufrieden. | B9: =ROUND(redflag_questions_scores!B128,2) -> 6.4
A10: Sie zeigt inkonsistenes Verhalten. Ihre Aussagen entsprechen nicht wie sich selbst gegenüber dir verhält. | B10: =ROUND(redflag_questions_scores!B162,2) -> 6.35
A11: Fakten und Logik spielen für sie kaum eine Rolle in der Bildung Ihrer Meinung. | B11: =ROUND(redflag_questions_scores!B164,2) -> 6.33
A12: Sie ist selbst verschuldet stark übergewichtig. | B12: =ROUND(redflag_questions_scores!B133,2) -> 6.3
A13: Sie ist stark tätoviert oder gepierct. (mehr als 4 Tatoos) | B13: =ROUND(redflag_questions_scores!B129,2) -> 6.28
A14: Sie lästert stark und häufig über andere Menschen. | B14: =ROUND(redflag_questions_scores!B167,2) -> 6.28
A15: Sie empfindet eine starke Eifersucht. | B15: =ROUND(redflag_questions_scores!B126,2) -> 6.17
A16: Sie ist eine Feministin und gibt Männer die Schuld an der Unterdrückung der Frauen. | B16: =ROUND(redflag_questions_scores!B110,2) -> 6.13
A17: Sie hat einen niedrigen Sexdrive mit dir und nicht so leidenschaftlich. | B17: =ROUND(redflag_questions_scores!B151,2) -> 6.07
A18: Sie ist im allgemeinen sehr verwöhnt und möchte häufig wie eine Prinzessin gehandelt werden. | B18: =ROUND(redflag_questions_scores!B138,2) -> 6
A19: Sie zeigt nicht viel Empathie für deine Gefühle. | B19: =ROUND(redflag_questions_scores!B159,2) -> 5.98
A20: Sie kann schlecht mit Geld umgehen. | B20: =ROUND(redflag_questions_scores!B137,2) -> 5.96
A21: Sie lügt häufig und entschuldigt sich dafür nicht. | B21: =ROUND(redflag_questions_scores!B140,2) -> 5.92
A22: Sie postet in Social Media sogenannte First Traps (Fotos die dazu dienen die männliche Aufmerksamkeit zu erregen). | B22: =ROUND(redflag_questions_scores!B154,2) -> 5.91
A23: Sie redet ohne Grund von selbst bei den Treffen häufig über Ihren Exfreund. | B23: =ROUND(redflag_questions_scores!B135,2) -> 5.87
A24: Sie ist Drogen oder Medikamenten Abhängig z.B. trinkt sehr häufig Alkohol Schlaftabletten Antidepressiva etc. | B24: =ROUND(redflag_questions_scores!B136,2) -> 5.86
A25: Sie bestraft dich mit Stille ohne es dir vorher zu kommunizieren dass Sie Ruhe braucht. | B25: =ROUND(redflag_questions_scores!B145,2) -> 5.83
A26: Sie kann sich nicht entspannen oder einfach mal nichts tun und muss ständig aktiv sein. | B26: =ROUND(redflag_questions_scores!B119,2) -> 5.81
A27: Sie kann nicht mit negativen Gefühlen von anderen Menschen umgehen und nimmt diese direkt auf. | B27: =ROUND(redflag_questions_scores!B163,2) -> 5.8
A28: Sie hat einen hohen Bodycount (Anzahl der Personen mit denen Sie Sex hatte). So kannst du einen normalen BodyCount berechnen: (Alter - 18) x 1.3 = BodyCount | B28: =ROUND(redflag_questions_scores!B114,2) -> 5.78
A29: Sie benutzt übermäßg häufig und starke MakeUps oder Cremes. | B29: =ROUND(redflag_questions_scores!B131,2) -> 5.73
A30: Sie stellt Ihre Karriere mit dir gleich oder über dich. | B30: =ROUND(redflag_questions_scores!B124,2) -> 5.72
A31: Sie nutzt Intimität als Belohnung aus. | B31: =ROUND(redflag_questions_scores!B143,2) -> 5.6
A32: Sie regiert häufig über und steigert sich häufig in Probleme. | B32: =ROUND(redflag_questions_scores!B158,2) -> 5.58
A33: Sie hat eher oberflächliche Schönheits Operationen über sich ergehen lassen besonders im Gesicht. | B33: =ROUND(redflag_questions_scores!B130,2) -> 5.56
A34: Sie antwortet dir nicht bei einer Meinungsverschiedenheit oder einem Konflikt und macht sich rar. | B34: =ROUND(redflag_questions_scores!B150,2) -> 5.52
A35: Sie trägt keine Verantwortung für Ihr Handeln und verdreht häufig die Realität. | B35: =ROUND(redflag_questions_scores!B146,2) -> 5.51
A36: Sie hat einen verfrühten Babywunsch für Ihr Alter. | B36: =ROUND(redflag_questions_scores!B139,2) -> 5.5
A37: Sie vermittelt dir den Glauben - Sie ist der Preis / wertvoll - du aber eher nicht. | B37: =ROUND(redflag_questions_scores!B142,2) -> 5.41
A38: Sie ist ein langzeit Single (4+ Jahre). | B38: =ROUND(redflag_questions_scores!B155,2) -> 5.4
A39: Einer ihrer Exfreunde war aus Ihrer Sicht besonders toxisch oder ein klassischer Badboy. | B39: =ROUND(redflag_questions_scores!B123,2) -> 5.33
A40: Sie hat häufig keine Zeit für dich. | B40: =ROUND(redflag_questions_scores!B166,2) -> 5.24
...

Sheet redflag_questions_scores
B4: Standard DEV | C4: =STDEV(redflag_questions!C2:redflag_questions!C66) -> 1.7613642 | D4: =STDEV(redflag_questions!D2:redflag_questions!D66) -> 2.8311455 | E4: =STDEV(redflag_questions!E2:redflag_questions!E66) -> 2.3057203 | F4: =STDEV(redflag_questions!F2:redflag_questions!F66) -> 2.1303665 | G4: =STDEV(redflag_questions!G2:redflag_questions!G66) -> 1.6767643 | H4: =STDEV(redflag_questions!H2:redflag_questions!H66) -> 2.0165183 | I4: =STDEV(redflag_questions!I2:redflag_questions!I66) -> 2.0652808 | J4: =STDEV(redflag_questions!J2:redflag_questions!J66) -> 2.4322552 | ... R4: =STDEV(redflag_questions!R2:redflag_questions!R66) -> 1.6916082 | S4: =STDEV(redflag_questions!S2:redflag_questions!S100) -> 2.3769729 | T4: =STDEV(redflag_questions!T2:redflag_questions!T100) -> 1.3696575 | U4: =STDEV(redflag_questions!U2:redflag_questions!U100) -> 1.9156491 | V4: =STDEV(redflag_questions!V2:redflag_questions!V100) -> 2.9053167 | W4: =STDEV(redflag_questions!W2:redflag_questions!W100) -> 2.2773973 | X4: =STDEV(redflag_questions!X2:redflag_questions!X100) -> 2.9813523 | Y4: =STDEV(redflag_questions!Y2:redflag_questions!Y100) -> 2.3168488 | Z4: =STDEV(redflag_questions!Z2:redflag_questions!Z100) -> 2.2668175
B5: Average | C5: =AVERAGE(redflag_questions!C2:redflag_questions!C66) -> 7.7384615 | D5: =AVERAGE(redflag_questions!D2:redflag_questions!D66) -> 7.0153846 | E5: =AVERAGE(redflag_questions!E2:redflag_questions!E66) -> 7.1076923 | F5: =AVERAGE(redflag_questions!F2:redflag_questions!F66) -> 5.1538462 | G5: =AVERAGE(redflag_questions!G2:redflag_questions!G66) -> 6.9692308 | H5: =AVERAGE(redflag_questions!H2:redflag_questions!H66) -> 7.5076923 | I5: =AVERAGE(redflag_questions!I2:redflag_questions!I66) -> 7.2153846 | J5: =AVERAGE(redflag_questions!J2:redflag_questions!J66) -> 5.9230769 | ... R5: =AVERAGE(redflag_questions!R2:redflag_questions!R66) -> 7.3692308 | S5: =AVERAGE(redflag_questions!S2:redflag_questions!S100) -> 5.6 | T5: =AVERAGE(redflag_questions!T2:redflag_questions!T100) -> 6.7538462 | U5: =AVERAGE(redflag_questions!U2:redflag_questions!U100) -> 5.0461538 | V5: =AVERAGE(redflag_questions!V2:redflag_questions!V100) -> 5.6769231 | W5: =AVERAGE(redflag_questions!W2:redflag_questions!W100) -> 7.5692308 | X5: =AVERAGE(redflag_questions!X2:redflag_questions!X100) -> 5.3538462 | Y5: =AVERAGE(redflag_questions!Y2:redflag_questions!Y100) -> 5.2307692 | Z5: =AVERAGE(redflag_questions!Z2:redflag_questions!Z100) -> 6.0461538
A6: =redflag_questions!A1 -> Questions | B6: =redflag_questions!B1 -> Weights | C6: =redflag_questions!C1 -> Lucas | D6: =redflag_questions!D1 -> Nicolaus | E6: =redflag_questions!E1 -> Alex | F6: =redflag_questions!F1 -> Alex | G6: =redflag_questions!G1 -> Stefan | H6: =redflag_questions!H1 -> Daniel | ... Z6: =redflag_questions!Z1 -> Maik | AA6: =#REF! -> #REF! | AB6: =#REF! -> #REF!
A7: =redflag_questions!A2 -> Sie ist zum größten Teil in ihrem Leben ohne biologischen Vater aufgewachsen. | B7: =redflag_questions!B2 -> 5.11 | C7: =STANDARDIZE(redflag_questions!C2,C$5,C$4) -> -0.41925545 | D7: =STANDARDIZE(redflag_questions!D2,D$5,D$4) -> -1.4182898 | E7: =STANDARDIZE(redflag_questions!E2,E$5,E$4) -> -0.91411447 | F7: =STANDARDIZE(redflag_questions!F2,F$5,F$4) -> -1.0110214 | G7: =STANDARDIZE(redflag_questions!G2,G$5,G$4) -> -0.57803639 | H7: =STANDARDIZE(redflag_questions!H2,H$5,H$4) -> -1.2435753 | I7: =STANDARDIZE(redflag_questions!I2,I$5,I$4) -> -0.1042883 | J7: =STANDARDIZE(redflag_questions!J2,J$5,J$4) -> 0.85390837 | ... Z7: =STANDARDIZE(redflag_questions!Z2,Z$5,Z$4) -> 0.42078648 | AA7: =STANDARDIZE(redflag_questions!Z2,AA$5,AA$4) -> #NUM!
A8: =redflag_questions!A3 -> Sie hat eine schlechte Beziehung zu ihrem Vater. | B8: =redflag_questions!B3 -> 4.26 | C8: =STANDARDIZE(redflag_questions!C3,C$5,C$4) -> -0.9869972 | D8: =STANDARDIZE(redflag_questions!D3,D$5,D$4) -> -0.0054340604 | E8: =STANDARDIZE(redflag_questions!E3,E$5,E$4) -> -0.046706579 | F8: =STANDARDIZE(redflag_questions!F3,F$5,F$4) -> -1.0110214 | G8: =STANDARDIZE(redflag_questions!G3,G$5,G$4) -> 0.018350362 | H8: =STANDARDIZE(redflag_questions!H3,H$5,H$4) -> -0.25176677 | I8: =STANDARDIZE(redflag_questions!I3,I$5,I$4) -> -0.58848397 | J8: =STANDARDIZE(redflag_questions!J3,J$5,J$4) -> -0.37951483 | ... Z8: =STANDARDIZE(redflag_questions!Z3,Z$5,Z$4) -> -0.46150775
A9: =redflag_questions!A4 -> Ihre Mutter hatte in der Eltern Beziehung das Sagen und war eher dominant. | B9: =redflag_questions!B4 -> 4.06 | C9: =STANDARDIZE(redflag_questions!C4,C$5,C$4) -> -1.554739 | D9: =STANDARDIZE(redflag_questions!D4,D$5,D$4) -> -0.35864799 | E9: =STANDARDIZE(redflag_questions!E4,E$5,E$4) -> -0.48041053 | F9: =STANDARDIZE(redflag_questions!F4,F$5,F$4) -> -1.0110214 | G9: =STANDARDIZE(redflag_questions!G4,G$5,G$4) -> 0.61473711 | H9: =STANDARDIZE(redflag_questions!H4,H$5,H$4) -> -0.25176677 | I9: =STANDARDIZE(redflag_questions!I4,I$5,I$4) -> -1.5568753 | J9: =STANDARDIZE(redflag_questions!J4,J$5,J$4) -> -0.37951483 | ... Z9: =STANDARDIZE(redflag_questions!Z4,Z$5,Z$4) -> -1.343802
A10: =redflag_questions!A5 -> Sie ist eine Feministin und gibt Männer die Schuld an der Unterdrückung der Frauen. | B10: =redflag_questions!B5 -> 6.13 | C10: =STANDARDIZE(redflag_questions!C5,C$5,C$4) -> 0.1484863 | D10: =STANDARDIZE(redflag_questions!D5,D$5,D$4) -> 1.0542077 | E10: =STANDARDIZE(redflag_questions!E5,E$5,E$4) -> 1.2544053 | F10: =STANDARDIZE(redflag_questions!F5,F$5,F$4) -> -0.072215814 | G10: =STANDARDIZE(redflag_questions!G5,G$5,G$4) -> 1.8075106 | H10: =STANDARDIZE(redflag_questions!H5,H$5,H$4) -> 0.74004172 | I10: =STANDARDIZE(redflag_questions!I5,I$5,I$4) -> 1.3482987 | J10: =STANDARDIZE(redflag_questions!J5,J$5,J$4) -> 1.6761905 | ... Z10: =STANDARDIZE(redflag_questions!Z5,Z$5,Z$4) -> 0.8619336
A11: =redflag_questions!A6 -> Sie ist eine Single Mutter die sich freiwillig von ihrem Mann getrennt hat. | B11: =redflag_questions!B6 -> 4.5 | C11: =STANDARDIZE(redflag_questions!C6,C$5,C$4) -> -1.554739 | D11: =STANDARDIZE(redflag_questions!D6,D$5,D$4) -> 1.0542077 | E11: =STANDARDIZE(redflag_questions!E6,E$5,E$4) -> -0.48041053 | F11: =STANDARDIZE(redflag_questions!F6,F$5,F$4) -> -1.4804242 | G11: =STANDARDIZE(redflag_questions!G6,G$5,G$4) -> 0.018350362 | H11: =STANDARDIZE(redflag_questions!H6,H$5,H$4) -> -2.731288 | I11: =STANDARDIZE(redflag_questions!I6,I$5,I$4) -> -2.5252666 | J11: =STANDARDIZE(redflag_questions!J6,J$5,J$4) -> 1.6761905 | ... Z11: =STANDARDIZE(redflag_questions!Z6,Z$5,Z$4) -> -0.90265487
A12: =redflag_questions!A7 -> Sie ist deutlich älter als du mindestens.5 Jahre oder mehr. | B12: =redflag_questions!B7 -> 4.78 | C12: =STANDARDIZE(redflag_questions!C7,C$5,C$4) -> 0.1484863 | D12: =STANDARDIZE(redflag_questions!D7,D$5,D$4) -> 0.34777986 | E12: =STANDARDIZE(redflag_questions!E7,E$5,E$4) -> -2.6489303 | F12: =STANDARDIZE(redflag_questions!F7,F$5,F$4) -> -1.0110214 | G12: =STANDARDIZE(redflag_questions!G7,G$5,G$4) -> -0.57803639 | H12: =STANDARDIZE(redflag_questions!H7,H$5,H$4) -> -1.2435753 | I12: =STANDARDIZE(redflag_questions!I7,I$5,I$4) -> 0.37990737 | J12: =STANDARDIZE(redflag_questions!J7,J$5,J$4) -> -1.201797 | ... Z12: =STANDARDIZE(redflag_questions!Z7,Z$5,Z$4) -> -1.7849491
A13: =redflag_questions!A8 -> Sie ist eine einfach oder mehrfach geschiedene Frau. | B13: =redflag_questions!B8 -> 6.43 | C13: =STANDARDIZE(redflag_questions!C8,C$5,C$4) -> 0.71622806 | D13: =STANDARDIZE(redflag_questions!D8,D$5,D$4) -> 1.0542077 | E13: =STANDARDIZE(redflag_questions!E8,E$5,E$4) -> 0.38699737 | F13: =STANDARDIZE(redflag_questions!F8,F$5,F$4) -> -0.072215814 | G13: =STANDARDIZE(redflag_questions!G8,G$5,G$4) -> -0.57803639 | H13: =STANDARDIZE(redflag_questions!H8,H$5,H$4) -> -2.2353838 | I13: =STANDARDIZE(redflag_questions!I8,I$5,I$4) -> -0.1042883 | J13: =STANDARDIZE(redflag_questions!J8,J$5,J$4) -> -0.37951483 | ... Z13: =STANDARDIZE(redflag_questions!Z8,Z$5,Z$4) -> 0.42078648
A14: =redflag_questions!A9 -> Sie hat einen hohen Bodycount (Anzahl der Personen mit denen Sie Sex hatte). So kannst du einen normalen BodyCount berechnen: (Alter - 18) x 1.3 = BodyCount | B14: =redflag_questions!B9 -> 5.78 | C14: =STANDARDIZE(redflag_questions!C9,C$5,C$4) -> 0.71622806 | D14: =STANDARDIZE(redflag_questions!D9,D$5,D$4) -> 1.0542077 | E14: =STANDARDIZE(redflag_questions!E9,E$5,E$4) -> 0.38699737 | F14: =STANDARDIZE(redflag_questions!F9,F$5,F$4) -> -0.072215814 | G14: =STANDARDIZE(redflag_questions!G9,G$5,G$4) -> -1.7708099 | H14: =STANDARDIZE(redflag_questions!H9,H$5,H$4) -> 0.74004172 | I14: =STANDARDIZE(redflag_questions!I9,I$5,I$4) -> 0.37990737 | J14: =STANDARDIZE(redflag_questions!J9,J$5,J$4) -> 0.4427673 | ... Z14: =STANDARDIZE(redflag_questions!Z9,Z$5,Z$4) -> 0.42078648
A15: =redflag_questions!A10 -> Sie war sehr jung (zwischen 12-16 Jahre) als Sie ihr erstes mal Sex hatte. | B15: =redflag_questions!B10 -> 4.35 | C15: =STANDARDIZE(redflag_questions!C10,C$5,C$4) -> 1.2839698 | D15: =STANDARDIZE(redflag_questions!D10,D$5,D$4) -> 1.0542077 | E15: =STANDARDIZE(redflag_questions!E10,E$5,E$4) -> 0.82070132 | F15: =STANDARDIZE(redflag_questions!F10,F$5,F$4) -> -1.4804242 | G15: =STANDARDIZE(redflag_questions!G10,G$5,G$4) -> -1.7708099 | H15: =STANDARDIZE(redflag_questions!H10,H$5,H$4) -> 1.235946 | I15: =STANDARDIZE(redflag_questions!I10,I$5,I$4) -> -1.0726796 | J15: =STANDARDIZE(redflag_questions!J10,J$5,J$4) -> 0.031626236 | ... Z15: =STANDARDIZE(redflag_questions!Z10,Z$5,Z$4) -> -0.46150775
A16: =redflag_questions!A11 -> Die meisten und besten Ihrer Freundinnen sind Party Girls. | B16: =redflag_questions!B11 -> 4.8 | C16: =STANDARDIZE(redflag_questions!C11,C$5,C$4) -> 0.71622806 | D16: =STANDARDIZE(redflag_questions!D11,D$5,D$4) -> 0.34777986 | E16: =STANDARDIZE(redflag_questions!E11,E$5,E$4) -> -0.48041053 | F16: =STANDARDIZE(redflag_questions!F11,F$5,F$4) -> -1.0110214 | G16: =STANDARDIZE(redflag_questions!G11,G$5,G$4) -> -1.7708099 | H16: =STANDARDIZE(redflag_questions!H11,H$5,H$4) -> -1.2435753 | I16: =STANDARDIZE(redflag_questions!I11,I$5,I$4) -> -2.041071 | J16: =STANDARDIZE(redflag_questions!J11,J$5,J$4) -> -0.37951483 | ... Z16: =STANDARDIZE(redflag_questions!Z11,Z$5,Z$4) -> 1.3030807
A17: =redflag_questions!A12 -> Sie ist auf Social Media sehr aktiv und sucht dort Bestätigung. Sie hat auf einer Plattform über 800 Follower. | B17: =redflag_questions!B12 -> 5.12 | C17: =STANDARDIZE(redflag_questions!C12,C$5,C$4) -> -0.9869972 | D17: =STANDARDIZE(redflag_questions!D12,D$5,D$4) -> -0.0054340604 | E17: =STANDARDIZE(redflag_questions!E12,E$5,E$4) -> 0.38699737 | F17: =STANDARDIZE(redflag_questions!F12,F$5,F$4) -> -0.072215814 | G17: =STANDARDIZE(redflag_questions!G12,G$5,G$4) -> -1.1744231 | H17: =STANDARDIZE(redflag_questions!H12,H$5,H$4) -> -0.25176677 | I17: =STANDARDIZE(redflag_questions!I12,I$5,I$4) -> 0.37990737 | J17: =STANDARDIZE(redflag_questions!J12,J$5,J$4) -> -0.7906559 | ... Z17: =STANDARDIZE(redflag_questions!Z12,Z$5,Z$4) -> -0.46150775
A18: =redflag_questions!A13 -> Sie hat sehr häufig ihr Smartphone bei euren Treffen in der Hand beziehungsweise legt das Handy direkt vor sich auf den Tisch. | B18: =redflag_questions!B13 -> 4.05 | C18: =STANDARDIZE(redflag_questions!C13,C$5,C$4) -> -1.554739 | D18: =STANDARDIZE(redflag_questions!D13,D$5,D$4) -> -1.0650758 | E18: =STANDARDIZE(redflag_questions!E13,E$5,E$4) -> -0.046706579 | F18: =STANDARDIZE(redflag_questions!F13,F$5,F$4) -> -0.54161861 | G18: =STANDARDIZE(redflag_questions!G13,G$5,G$4) -> 0.61473711 | H18: =STANDARDIZE(redflag_questions!H13,H$5,H$4) -> 0.24413748 | I18: =STANDARDIZE(redflag_questions!I13,I$5,I$4) -> -0.58848397 | J18: =STANDARDIZE(redflag_questions!J13,J$5,J$4) -> -0.7906559 | ... Z18: =STANDARDIZE(redflag_questions!Z13,Z$5,Z$4) -> 0.8619336
A19: =redflag_questions!A14 -> Sie kann sich nicht entspannen oder einfach mal nichts tun und muss ständig aktiv sein. | B19: =redflag_questions!B14 -> 5.81 | C19: =STANDARDIZE(redflag_questions!C14,C$5,C$4) -> 0.1484863 | D19: =STANDARDIZE(redflag_questions!D14,D$5,D$4) -> -2.1247176 | E19: =STANDARDIZE(redflag_questions!E14,E$5,E$4) -> 0.38699737 | F19: =STANDARDIZE(redflag_questions!F14,F$5,F$4) -> 0.86658977 | G19: =STANDARDIZE(redflag_questions!G14,G$5,G$4) -> 0.61473711 | H19: =STANDARDIZE(redflag_questions!H14,H$5,H$4) -> -2.2353838 | I19: =STANDARDIZE(redflag_questions!I14,I$5,I$4) -> -0.58848397 | J19: =STANDARDIZE(redflag_questions!J14,J$5,J$4) -> 0.031626236 | ... Z19: =STANDARDIZE(redflag_questions!Z14,Z$5,Z$4) -> -1.343802
... A71: =redflag_questions!A66 -> Sie kann nicht klar kommunizieren. | B71: =redflag_questions!B66 -> 4.79 | C71: =STANDARDIZE(redflag_questions!C66,C$5,C$4) -> 1.2839698 | D71: =STANDARDIZE(redflag_questions!D66,D$5,D$4) -> 0.34777986 | E71: =STANDARDIZE(redflag_questions!E66,E$5,E$4) -> -0.91411447 | F71: =STANDARDIZE(redflag_questions!F66,F$5,F$4) -> -0.54161861 | G71: =STANDARDIZE(redflag_questions!G66,G$5,G$4) -> -1.1744231 | H71: =STANDARDIZE(redflag_questions!H66,H$5,H$4) -> 0.74004172 | I71: =STANDARDIZE(redflag_questions!I66,I$5,I$4) -> -1.0726796 | J71: =STANDARDIZE(redflag_questions!J66,J$5,J$4) -> -0.7906559 | ... Z71: =STANDARDIZE(redflag_questions!Z66,Z$5,Z$4) -> -0.46150775
A72: =redflag_questions!A67 | B72: =redflag_questions!B67 | C72: =redflag_questions!C67 | D72: =redflag_questions!D67 | E72: =redflag_questions!E67 | F72: =redflag_questions!F67 | G72: =redflag_questions!G67 | H72: =redflag_questions!H67 | ... M72: =redflag_questions!M67
A73: =redflag_questions!A68 | B73: =redflag_questions!B68 | C73: =redflag_questions!C68 | D73: =redflag_questions!D68 | E73: =redflag_questions!E68 | F73: =redflag_questions!F68 | G73: =redflag_questions!G68 | H73: =redflag_questions!H68 | ... M73: =redflag_questions!M68
A74: =redflag_questions!A69 | B74: =redflag_questions!B69 | C74: =redflag_questions!C69 | D74: =redflag_questions!D69 | E74: =redflag_questions!E69 | F74: =redflag_questions!F69 | G74: =redflag_questions!G69 | H74: =redflag_questions!H69 | ... M74: =redflag_questions!M69
A75: =redflag_questions!A70 | B75: =redflag_questions!B70 | C75: =redflag_questions!C70 | D75: =redflag_questions!D70 | E75: =redflag_questions!E70 | F75: =redflag_questions!F70 | G75: =redflag_questions!G70 | H75: =redflag_questions!H70 | ... M75: =redflag_questions!M70
A76: =redflag_questions!A71 | B76: =redflag_questions!B71 | C76: =redflag_questions!C71 | D76: =redflag_questions!D71 | E76: =redflag_questions!E71 | F76: =redflag_questions!F71 | G76: =redflag_questions!G71 | H76: =redflag_questions!H71 | ... M76: =redflag_questions!M71
A77: =redflag_questions!A72 | B77: =redflag_questions!B72 | C77: =redflag_questions!C72 | D77: =redflag_questions!D72 | E77: =redflag_questions!E72 | F77: =redflag_questions!F72 | G77: =redflag_questions!G72 | H77: =redflag_questions!H72 | ... M77: =redflag_questions!M72
A78: =redflag_questions!A73 | B78: =redflag_questions!B73 | C78: =redflag_questions!C73 | D78: =redflag_questions!D73 | E78: =redflag_questions!E73 | F78: =redflag_questions!F73 | G78: =redflag_questions!G73 | H78: =redflag_questions!H73 | ... M78: =redflag_questions!M73
A79: =redflag_questions!A74 | B79: =redflag_questions!B74 | C79: =redflag_questions!C74 | D79: =redflag_questions!D74 | E79: =redflag_questions!E74 | F79: =redflag_questions!F74 | G79: =redflag_questions!G74 | H79: =redflag_questions!H74 | ... M79: =redflag_questions!M74
A80: =redflag_questions!A75 | B80: =redflag_questions!B75 | C80: =redflag_questions!C75 | D80: =redflag_questions!D75 | E80: =redflag_questions!E75 | F80: =redflag_questions!F75 | G80: =redflag_questions!G75 | H80: =redflag_questions!H75 | ... M80: =redflag_questions!M75
A81: =redflag_questions!A76 | B81: =redflag_questions!B76 | C81: =redflag_questions!C76 | D81: =redflag_questions!D76 | E81: =redflag_questions!E76 | F81: =redflag_questions!F76 | G81: =redflag_questions!G76 | H81: =redflag_questions!H76 | ... M81: =redflag_questions!M76
A82: =redflag_questions!A77 | B82: =redflag_questions!B77 | C82: =redflag_questions!C77 | D82: =redflag_questions!D77 | E82: =redflag_questions!E77 | F82: =redflag_questions!F77 | G82: =redflag_questions!G77 | H82: =redflag_questions!H77 | ... M82: =redflag_questions!M77
A83: =redflag_questions!A78 | B83: =redflag_questions!B78 | C83: =redflag_questions!C78 | D83: =redflag_questions!D78 | E83: =redflag_questions!E78 | F83: =redflag_questions!F78 | G83: =redflag_questions!G78 | H83: =redflag_questions!H78 | ... M83: =redflag_questions!M78
... A105: =redflag_questions!A100 | B105: =redflag_questions!B100 | C105: =redflag_questions!C100 | D105: =redflag_questions!D100 | E105: =redflag_questions!E100 | F105: =redflag_questions!F100 | G105: =redflag_questions!G100 | H105: =redflag_questions!H100 | ... M105: =redflag_questions!M100
A106: =redflag_questions!A1 -> Questions | B106: =redflag_questions!B1 -> Weights | C106: =redflag_questions!C1 -> Lucas | D106: =redflag_questions!D1 -> Nicolaus | E106: =redflag_questions!E1 -> Alex | F106: =redflag_questions!F1 -> Alex | G106: =redflag_questions!G1 -> Stefan | H106: =redflag_questions!H1 -> Daniel | ... Z106: =redflag_questions!Z1 -> Maik | AA106: Max | AB106: Min
A107: =redflag_questions!A2 -> Sie ist zum größten Teil in ihrem Leben ohne biologischen Vater aufgewachsen. | B107: =AVERAGE(C107:Z107)*10 -> 5.1141637 | C107: =(C7-$AB107)/($AA107-$AB107) -> 0.61411619 | D107: =(D7-$AB107)/($AA107-$AB107) -> 0.31131842 | E107: =(E7-$AB107)/($AA107-$AB107) -> 0.46412914 | F107: =(F7-$AB107)/($AA107-$AB107) -> 0.43475757 | G107: =(G7-$AB107)/($AA107-$AB107) -> 0.5659912 | H107: =(H7-$AB107)/($AA107-$AB107) -> 0.36427272 | I107: =(I7-$AB107)/($AA107-$AB107) -> 0.70957973 | J107: =(J7-$AB107)/($AA107-$AB107) -> 1 | ... Z107: =(Z7-$AB107)/($AA107-$AB107) -> 0.86872489 | AA107: =MAX(E7:Z7) -> 0.85390837 | AB107: =MIN(E7:Z7) -> -2.4454366
A108: =redflag_questions!A3 -> Sie hat eine schlechte Beziehung zu ihrem Vater. | B108: =AVERAGE(C108:Z108)*10 -> 4.2587522 | C108: =(C8-$AB108)/($AA108-$AB108) -> 0.37762499 | D108: =(D8-$AB108)/($AA108-$AB108) -> 0.72658451 | E108: =(E8-$AB108)/($AA108-$AB108) -> 0.71191155 | F108: =(F8-$AB108)/($AA108-$AB108) -> 0.36908405 | G108: =(G8-$AB108)/($AA108-$AB108) -> 0.73504021 | H108: =(H8-$AB108)/($AA108-$AB108) -> 0.63900976 | I108: =(I8-$AB108)/($AA108-$AB108) -> 0.51930206 | J108: =(J8-$AB108)/($AA108-$AB108) -> 0.59359353 | ... Z108: =(Z8-$AB108)/($AA108-$AB108) -> 0.56444389 | AA108: =MAX(E8:Z8) -> 0.76363669 | AB108: =MIN(E8:Z8) -> -2.0491914
A109: =redflag_questions!A4 -> Ihre Mutter hatte in der Eltern Beziehung das Sagen und war eher dominant. | B109: =AVERAGE(C109:Z109)*10 -> 4.0648406 | C109: =(C9-$AB109)/($AA109-$AB109) -> 0.17229563 | D109: =(D9-$AB109)/($AA109-$AB109) -> 0.62863149 | E109: =(E9-$AB109)/($AA109-$AB109) -> 0.58217631 | F109: =(F9-$AB109)/($AA109-$AB109) -> 0.37973622 | G109: =(G9-$AB109)/($AA109-$AB109) -> 1 | H109: =(H9-$AB109)/($AA109-$AB109) -> 0.6694091 | I109: =(I9-$AB109)/($AA109-$AB109) -> 0.17148056 | J109: =(J9-$AB109)/($AA109-$AB109) -> 0.62067031 | ... Z109: =(Z9-$AB109)/($AA109-$AB109) -> 0.25277287 | AA109: =MAX(E9:Z9) -> 0.61473711 | AB109: =MIN(E9:Z9) -> -2.0063389
A110: =redflag_questions!A5 -> Sie ist eine Feministin und gibt Männer die Schuld an der Unterdrückung der Frauen. | B110: =AVERAGE(C110:Z110)*10 -> 6.1286911 | C110: =(C10-$AB110)/($AA110-$AB110) -> 0.54342111 | D110: =(D10-$AB110)/($AA110-$AB110) -> 0.79268405 | E110: =(E10-$AB110)/($AA110-$AB110) -> 0.84778027 | F110: =(F10-$AB110)/($AA110-$AB110) -> 0.48268184 | G110: =(G10-$AB110)/($AA110-$AB110) -> 1 | H110: =(H10-$AB110)/($AA110-$AB110) -> 0.70622265 | I110: =(I10-$AB110)/($AA110-$AB110) -> 0.87362062 | J110: =(J10-$AB110)/($AA110-$AB110) -> 0.96385949 | ... Z110: =(Z10-$AB110)/($AA110-$AB110) -> 0.73976843 | AA110: =MAX(E10:Z10) -> 1.8075106 | AB110: =MIN(E10:Z10) -> -1.8260877
A111: =redflag_questions!A6 -> Sie ist eine Single Mutter die sich freiwillig von ihrem Mann getrennt hat. | B111: =AVERAGE(C111:Z111)*10 -> 4.4996646 | C111: =(C11-$AB111)/($AA111-$AB111) -> 0.2669438 | D111: =(D11-$AB111)/($AA111-$AB111) -> 0.85888013 | E111: =(E11-$AB111)/($AA111-$AB111) -> 0.51069505 | F111: =(F11-$AB111)/($AA111-$AB111) -> 0.28380486 | G111: =(G11-$AB111)/($AA111-$AB111) -> 0.62385746 | H111: =(H11-$AB111)/($AA111-$AB111) -> 0 | I111: =(I11-$AB111)/($AA111-$AB111) -> 0.046743588 | J111: =(J11-$AB111)/($AA111-$AB111) -> 1 | ... Z111: =(Z11-$AB111)/($AA111-$AB111) -> 0.41489326 | AA111: =MAX(E11:Z11) -> 1.6761905 | AB111: =MIN(E11:Z11) -> -2.731288
A112: =redflag_questions!A7 -> Sie ist deutlich älter als du mindestens.5 Jahre oder mehr. | B112: =AVERAGE(C112:Z112)*10 -> 4.7758933 | C112: =(C12-$AB112)/($AA112-$AB112) -> 0.66750004 | D112: =(D12-$AB112)/($AA112-$AB112) -> 0.71505408 | E112: =(E12-$AB112)/($AA112-$AB112) -> 0 | F112: =(F12-$AB112)/($AA112-$AB112) -> 0.39082639 | G112: =(G12-$AB112)/($AA112-$AB112) -> 0.49414226 | H112: =(H12-$AB112)/($AA112-$AB112) -> 0.33533601 | I112: =(I12-$AB112)/($AA112-$AB112) -> 0.72272012 | J112: =(J12-$AB112)/($AA112-$AB112) -> 0.34530486 | ... Z112: =(Z12-$AB112)/($AA112-$AB112) -> 0.20615716 | AA112: =MAX(E12:Z12) -> 1.5419557 | AB112: =MIN(E12:Z12) -> -2.6489303
A113: =redflag_questions!A8 -> Sie ist eine einfach oder mehrfach geschiedene Frau. | B113: =AVERAGE(C113:Z113)*10 -> 6.4268024 | C113: =(C13-$AB113)/($AA113-$AB113) -> 0.85418731 | D113: =(D13-$AB113)/($AA113-$AB113) -> 0.95199757 | E113: =(E13-$AB113)/($AA113-$AB113) -> 0.75890897 | F113: =(F13-$AB113)/($AA113-$AB113) -> 0.6260141 | G113: =(G13-$AB113)/($AA113-$AB113) -> 0.47963119 | H113: =(H13-$AB113)/($AA113-$AB113) -> 0 | I113: =(I13-$AB113)/($AA113-$AB113) -> 0.61673242 | J113: =(J13-$AB113)/($AA113-$AB113) -> 0.53708271 | ... Z113: =(Z13-$AB113)/($AA113-$AB113) -> 0.76868743 | AA113: =MAX(E13:Z13) -> 1.2200783 | AB113: =MIN(E13:Z13) -> -2.2353838
A114: =redflag_questions!A9 -> Sie hat einen hohen Bodycount (Anzahl der Personen mit denen Sie Sex hatte). So kannst du einen normalen BodyCount berechnen: (Alter - 18) x 1.3 = BodyCount | B114: =AVERAGE(C114:Z114)*10 -> 5.7771629 | C114: =(C14-$AB114)/($AA114-$AB114) -> 0.83153826 | D114: =(D14-$AB114)/($AA114-$AB114) -> 0.94454137 | E114: =(E14-$AB114)/($AA114-$AB114) -> 0.72146036 | F114: =(F14-$AB114)/($AA114-$AB114) -> 0.56792296 | G114: =(G14-$AB114)/($AA114-$AB114) -> 0 | H114: =(H14-$AB114)/($AA114-$AB114) -> 0.83950033 | I114: =(I14-$AB114)/($AA114-$AB114) -> 0.71908983 | J114: =(J14-$AB114)/($AA114-$AB114) -> 0.74010697 | ... Z114: =(Z14-$AB114)/($AA114-$AB114) -> 0.73275771 | AA114: =MAX(E14:Z14) -> 1.2200783 | AB114: =MIN(E14:Z14) -> -1.7708099
A115: =redflag_questions!A10 -> Sie war sehr jung (zwischen 12-16 Jahre) als Sie ihr erstes mal Sex hatte. | B115: =AVERAGE(C115:Z115)*10 -> 4.3476815 | C115: =(C15-$AB115)/($AA115-$AB115) -> 1.0130451 | D115: =(D15-$AB115)/($AA115-$AB115) -> 0.95063315 | E115: =(E15-$AB115)/($AA115-$AB115) -> 0.88720416 | F115: =(F15-$AB115)/($AA115-$AB115) -> 0.26213315 | G115: =(G15-$AB115)/($AA115-$AB115) -> 0.18325363 | H115: =(H15-$AB115)/($AA115-$AB115) -> 1 | I115: =(I15-$AB115)/($AA115-$AB115) -> 0.37289169 | J115: =(J15-$AB115)/($AA115-$AB115) -> 0.67286211 | ... Z115: =(Z15-$AB115)/($AA115-$AB115) -> 0.53890864 | AA115: =MAX(E15:Z15) -> 1.235946 | AB115: =MIN(E15:Z15) -> -2.4454366
...
